<?xml version="1.0" ?>
<!-- =================================================================================== -->
<!-- |    This document was autogenerated by xacro from /home/dwq/chonk/src/chonk_pushing/urdf/chonk_pushing.urdf.xacro | -->
<!-- |    EDITING THIS FILE BY HAND IS NOT RECOMMENDED                                 | -->
<!-- =================================================================================== -->
<robot name="chonk">
  <material name="Black">
    <color rgba="0.0 0.0 0.0 1.0"/>
  </material>
  <material name="Blue">
    <color rgba="0.0 0.0 0.8 1.0"/>
  </material>
  <material name="Green">
    <color rgba="0.0 0.8 0.0 1.0"/>
  </material>
  <material name="LightGrey">
    <color rgba="0.6 0.6 0.6 1.0"/>
  </material>
  <material name="Grey">
    <color rgba="0.4 0.4 0.4 1.0"/>
  </material>
  <material name="DarkGrey">
    <color rgba="0.2 0.2 0.2 1.0"/>
  </material>
  <material name="Red">
    <color rgba="0.8 0.0 0.0 1.0"/>
  </material>
  <material name="White">
    <color rgba="1.0 1.0 1.0 1.0"/>
  </material>
  <material name="aluminum">
    <color rgba="0.5 0.5 0.5 1"/>
  </material>
  <material name="plastic">
    <color rgba="0.1 0.1 0.1 1"/>
  </material>

<!-- Base link-->
<link name="base_link"/>


<link name="donkey_pre1"/>
<joint name="base_joint_1" type="prismatic">
  <parent link="base_link"/>
  <child link="donkey_pre1"/>
  <axis xyz="1 0 0"/>
  <origin xyz="0 0 0" rpy="0 0 0"/>
  <limit effort="100" lower="-100000" upper="100000" velocity="1.5"/>
  <dynamics damping="0.2" friction="0"/>
</joint>

<transmission name="base_joint_1_Trans">
  <type>transmission_interface/SimpleTransmission</type>
  <joint name="base_joint_1">
    <hardwareInterface>hardware_interface/PositionJointInterface</hardwareInterface>
  </joint>
  <actuator name="base_joint_1_Motor">
    <mechanicalReduction>1</mechanicalReduction>
  </actuator>
</transmission>

<link name="donkey_pre2"/>
<joint name="base_joint_2" type="prismatic">
  <parent link="donkey_pre1"/>
  <child link="donkey_pre2"/>
  <axis xyz="0 1 0"/>
  <origin xyz="0 0 0" rpy="0 0 0"/>
  <limit effort="100" lower="-100000" upper="100000" velocity="1.5"/>
  <dynamics damping="0.2" friction="0"/>
</joint>



<transmission name="base_joint_2_Trans">
  <type>transmission_interface/SimpleTransmission</type>
  <joint name="base_joint_2">
    <hardwareInterface>hardware_interface/PositionJointInterface</hardwareInterface>
  </joint>
  <actuator name="base_joint_2_Motor">
    <mechanicalReduction>1</mechanicalReduction>
  </actuator>
</transmission>

<link name="donkey_base">
  <inertial>
    <mass value="200.0"/>
    <origin rpy="0 0 0" xyz="0.0 0.0 0.4485"/>
    <inertia ixx="21.14963333333333" ixy="0.0" ixz="0.0" iyy="29.71963333333333" iyz="0.0" izz="25.23163333333333"/>
  </inertial>
  <visual>
    <origin rpy="0 0 0" xyz="0.0 0.0 0.0"/>
    <geometry>
      <mesh filename="package://donkey_description/meshes/donkey_colourised_decimated.dae"/>
    </geometry>
  </visual>
  <collision>
    <origin rpy="0 0 0" xyz="0.0 0.0 0.4885"/>
    <geometry>
      <box size="1.007 0.707 0.727"/>
    </geometry>
  </collision>
</link>
<gazebo reference="donkey_base">
  <dampingFactor>0.001</dampingFactor>
</gazebo>


<joint name="base_joint_3" type="revolute">
  <parent link="donkey_pre2"/>
  <child link="donkey_base"/>
  <origin xyz="0 0 0" rpy="0 0 0"/>
  <axis xyz="0 0 1"/>
  <limit effort="100" lower="-300000.14159" upper="300000.14159" velocity="2"/>
  <dynamics damping="0.2" friction="0"/>
</joint>


<transmission name="base_joint_3_Trans">
  <type>transmission_interface/SimpleTransmission</type>
  <joint name="base_joint_3">
    <hardwareInterface>hardware_interface/PositionJointInterface</hardwareInterface>
  </joint>
  <actuator name="base_joint_3_Motor">
    <mechanicalReduction>1</mechanicalReduction>
  </actuator>
</transmission>

<!-- donkey_link reference -->
<link name="link_donkey"/>
<joint name="link_donkey_joint" type="fixed">
  <parent link="donkey_base"/>
  <child link="link_donkey"/>
  <origin rpy="0 0 0" xyz="0 0 0"/>
</joint>

<joint name="donkey_base_mount_joint" type="fixed">
  <child link="WAIST"/>
  <parent link="donkey_base"/>
  <origin rpy="0 0 0" xyz="0.422 0.0 0.855"/>
</joint>

  <!-- NOTE: The poses of headmount and hand cameras are NOT precisely adjusted to
    the 3D model nor the actual hardware config. These configs
    are meant for a rapid prototyping only. -->
  <joint name="CAMERA_HEAD_L" type="fixed">
    <origin rpy="0 0.25 0" xyz="0.0175 0.0725 0.105"/>
    <parent link="HEAD_JOINT1_Link"/>
    <child link="CAMERA_HEAD_L_Link"/>
  </joint>
  <link name="CAMERA_HEAD_L_Link">
    <visual>
      <origin rpy="0 1.5707963267948966 -0.05" xyz="0.0325 0 0"/>
      <geometry>
        <cylinder length="0.01" radius="0.015"/>
      </geometry>
      <material name="Blue"/>
    </visual>
    <inertial>
      <origin rpy="0 0 0" xyz="0 0 0"/>
      <mass value="1e-6"/>
      <inertia ixx="1e-12" ixy="0.0" ixz="0.0" iyy="1e-12" iyz="0.0" izz="1e-12"/>
    </inertial>
  </link>
  <gazebo reference="CAMERA_HEAD_L_Link">
    <sensor name="CAMERA_HEAD_L" type="camera">
      <update_rate>30.0</update_rate>
      <camera name="CAMERA_HEAD_L">
        <horizontal_fov>1.3962634</horizontal_fov>
        <image>
          <width>800</width>
          <height>800</height>
          <format>R8G8B8</format>
        </image>
        <clip>
          <near>0.1</near>
          <far>30</far>
        </clip>
        <noise>
          <type>gaussian</type>
          <!-- Noise is sampled independently per pixel on each frame. That pixel's
                        noise value is added to each of its color channels, which at that point lie
                        in the range [0,1]. -->
          <mean>0.0</mean>
          <stddev>0.007</stddev>
        </noise>
      </camera>
      <plugin filename="libgazebo_ros_camera.so" name="camera_controller">
        <alwaysOn>true</alwaysOn>
        <updateRate>0.0</updateRate>
        <cameraName>CAMERA_HEAD_L</cameraName>
        <imageTopicName>image_raw</imageTopicName>
        <cameraInfoTopicName>camera_info</cameraInfoTopicName>
        <frameName>CAMERA_HEAD_L_Link_frame</frameName>
        <hackBaseline>0.07</hackBaseline>
        <distortionK1>0.0</distortionK1>
        <distortionK2>0.0</distortionK2>
        <distortionK3>0.0</distortionK3>
        <distortionT1>0.0</distortionT1>
        <distortionT2>0.0</distortionT2>
      </plugin>
    </sensor>
  </gazebo>
  <joint name="CAMERA_HEAD_R" type="fixed">
    <origin rpy="0 0.25 0" xyz="0.0175 -0.0725 0.105"/>
    <parent link="HEAD_JOINT1_Link"/>
    <child link="CAMERA_HEAD_R_Link"/>
  </joint>
  <link name="CAMERA_HEAD_R_Link">
    <visual>
      <origin rpy="0 1.5707963267948966 0.05" xyz="0.0325 0 0"/>
      <geometry>
        <cylinder length="0.01" radius="0.015"/>
      </geometry>
      <material name="Blue"/>
    </visual>
    <inertial>
      <origin rpy="0 0 0" xyz="0 0 0"/>
      <mass value="1e-6"/>
      <inertia ixx="1e-12" ixy="0.0" ixz="0.0" iyy="1e-12" iyz="0.0" izz="1e-12"/>
    </inertial>
  </link>
  <gazebo reference="CAMERA_HEAD_R_Link">
    <sensor name="CAMERA_HEAD_R" type="camera">
      <update_rate>30.0</update_rate>
      <camera name="CAMERA_HEAD_R">
        <horizontal_fov>1.3962634</horizontal_fov>
        <image>
          <width>800</width>
          <height>800</height>
          <format>R8G8B8</format>
        </image>
        <clip>
          <near>0.1</near>
          <far>30</far>
        </clip>
        <noise>
          <type>gaussian</type>
          <!-- Noise is sampled independently per pixel on each frame. That pixel's
                        noise value is added to each of its color channels, which at that point lie
                        in the range [0,1]. -->
          <mean>0.0</mean>
          <stddev>0.007</stddev>
        </noise>
      </camera>
      <plugin filename="libgazebo_ros_camera.so" name="camera_controller">
        <alwaysOn>true</alwaysOn>
        <updateRate>0.0</updateRate>
        <cameraName>CAMERA_HEAD_R</cameraName>
        <imageTopicName>image_raw</imageTopicName>
        <cameraInfoTopicName>camera_info</cameraInfoTopicName>
        <frameName>CAMERA_HEAD_R_Link_frame</frameName>
        <hackBaseline>0.07</hackBaseline>
        <distortionK1>0.0</distortionK1>
        <distortionK2>0.0</distortionK2>
        <distortionK3>0.0</distortionK3>
        <distortionT1>0.0</distortionT1>
        <distortionT2>0.0</distortionT2>
      </plugin>
    </sensor>
  </gazebo>
  <gazebo reference="gazebo_WAIST">
    <material>Gazebo/Black</material>
    <mu1 value="1.0"/>
    <mu2 value="1.0"/>
    <kp value="1e5"/>
    <kd value="1e2"/>
    <maxVel value="100.0"/>
    <minDepth value="0.0"/>
    <dampingFactor>0.01</dampingFactor>
  </gazebo>
  <link name="WAIST">
    <visual>
      <origin rpy="0 0 0" xyz="0 0 0"/>
      <geometry>
        <mesh filename="package://nextagea_description/urdf/meshes/WAIST_Link_mesh.dae"/>
      </geometry>
    </visual>
    <collision>
      <origin rpy="0 0 0" xyz="0.0 0 0.098"/>
      <geometry>
        <cylinder length="0.376" radius="0.06"/>
      </geometry>
    </collision>
    <inertial>
      <mass value="5"/>
      <origin rpy="0 0 0" xyz="0 0 0.15"/>
      <inertia ixx="0.05416666666666667" ixy="0.0" ixz="0.0" iyy="0.05416666666666667" iyz="0.0" izz="0.03333333333333334"/>
    </inertial>
  </link>
  <gazebo reference="gazebo_CHEST_JOINT0_Link">
    <material>Gazebo/Black</material>
    <mu1 value="1.0"/>
    <mu2 value="1.0"/>
    <kp value="1e5"/>
    <kd value="1e2"/>
    <maxVel value="100.0"/>
    <minDepth value="0.0"/>
    <dampingFactor>0.01</dampingFactor>
  </gazebo>
  <link name="CHEST_JOINT0_Link">
    <visual>
      <origin rpy="0 0 0" xyz="0 0 0"/>
      <geometry>
        <mesh filename="package://nextagea_description/urdf/meshes/CHEST_JOINT0_Link_mesh.dae"/>
      </geometry>
    </visual>
    <collision>
      <origin rpy="0 0 0" xyz="0 0 0.1575"/>
      <geometry>
        <cylinder length="0.385" radius="0.08"/>
      </geometry>
    </collision>
    <collision>
      <origin rpy="0 0 0" xyz="0.04 0.135 0.0423"/>
      <geometry>
        <cylinder length="0.09" radius="0.05"/>
      </geometry>
    </collision>
    <collision>
      <origin rpy="0 0 0" xyz="0.04 -0.135 0.0423"/>
      <geometry>
        <cylinder length="0.09" radius="0.05"/>
      </geometry>
    </collision>
    <collision>
      <origin rpy="0 0 0" xyz="0 0 0.055"/>
      <geometry>
        <box size="0.23 0.18 0.12"/>
      </geometry>
    </collision>
    <collision>
      <origin rpy="0 0 0" xyz="-0.04 0 0.2325"/>
      <geometry>
        <box size="0.25 0.18 0.245"/>
      </geometry>
    </collision>
    <collision>
      <origin rpy="0 0 0" xyz="-0.1525 0 0.279"/>
      <geometry>
        <box size="0.17 0.29 0.225"/>
      </geometry>
    </collision>
    <collision>
      <origin rpy="0 0 0" xyz="0.03 0 0.315"/>
      <geometry>
        <box size="0.085 0.5 0.0365"/>
      </geometry>
    </collision>
    <inertial>
      <mass value="10.0"/>
      <origin rpy="0 -0 0" xyz="0 0 0.2"/>
      <inertia ixx="0.12708333333333333" ixy="0.0" ixz="0.0" iyy="0.12708333333333333" iyz="0.0" izz="0.10416666666666667"/>
    </inertial>
  </link>
  <gazebo reference="gazebo_HEAD_JOINT0_Link">
    <material>Gazebo/Black</material>
    <mu1 value="1.0"/>
    <mu2 value="1.0"/>
    <kp value="1e5"/>
    <kd value="1e2"/>
    <maxVel value="100.0"/>
    <minDepth value="0.0"/>
    <dampingFactor>0.01</dampingFactor>
  </gazebo>
  <link name="HEAD_JOINT0_Link">
    <visual>
      <origin rpy="0 0 0" xyz="0 0 0"/>
      <geometry>
        <mesh filename="package://nextagea_description/urdf/meshes/HEAD_JOINT0_Link_mesh.dae"/>
      </geometry>
    </visual>
    <collision>
      <origin rpy="1.57079 0 0" xyz="0 0.01 0.08"/>
      <geometry>
        <cylinder length="0.135" radius="0.035"/>
      </geometry>
    </collision>
    <inertial>
      <mass value="0.317929"/>
      <origin rpy="0 -0 0" xyz="0 0.00547848 0"/>
      <inertia ixx="0.0005298816666666668" ixy="0.0" ixz="0.0" iyy="0.0005298816666666668" iyz="0.0" izz="0.0005298816666666668"/>
    </inertial>
  </link>
  <gazebo reference="gazebo_HEAD_JOINT1_Link">
    <material>Gazebo/Black</material>
    <mu1 value="1.0"/>
    <mu2 value="1.0"/>
    <kp value="1e5"/>
    <kd value="1e2"/>
    <maxVel value="100.0"/>
    <minDepth value="0.0"/>
    <dampingFactor>0.01</dampingFactor>
  </gazebo>
  <link name="HEAD_JOINT1_Link">
    <visual>
      <origin rpy="0 0 0" xyz="0 0 0"/>
      <geometry>
        <mesh filename="package://nextagea_description/urdf/meshes/HEAD_JOINT1_Link_mesh.dae"/>
      </geometry>
    </visual>
    <collision>
      <origin rpy="0 0.26 0" xyz="-0.05 0 0.12"/>
      <geometry>
        <box size="0.27 0.22 0.115"/>
      </geometry>
    </collision>
    <inertial>
      <mass value="0.4"/>
      <origin rpy="0 0.26 0" xyz="-0.05 0 0.12"/>
      <inertia ixx="0.002054166666666667" ixy="0.0" ixz="0.0" iyy="0.0028708333333333333" iyz="0.0" izz="0.004043333333333334"/>
    </inertial>
  </link>
  <gazebo reference="gazebo_LARM_JOINT0_Link">
    <material>Gazebo/Black</material>
    <mu1 value="1.0"/>
    <mu2 value="1.0"/>
    <kp value="1e5"/>
    <kd value="1e2"/>
    <maxVel value="100.0"/>
    <minDepth value="0.0"/>
    <dampingFactor>0.01</dampingFactor>
  </gazebo>
  <link name="LARM_JOINT0_Link">
    <visual>
      <origin rpy="0 0 0" xyz="0 0 0"/>
      <geometry>
        <mesh filename="package://nextagea_description/urdf/meshes/LARM_JOINT0_Link_mesh.dae"/>
      </geometry>
    </visual>
    <collision>
      <origin rpy="0 0 0" xyz="0 0.00775 0.095"/>
      <geometry>
        <box size="0.1 0.0815 0.19"/>
      </geometry>
    </collision>
    <collision>
      <origin rpy="1.57079 0 0" xyz="0 0.0875 0.066"/>
      <geometry>
        <cylinder length="0.175" radius="0.042"/>
      </geometry>
    </collision>
    <collision>
      <origin rpy="-0.7 0 0" xyz="0 0.125 0.145"/>
      <geometry>
        <box size="0.048 0.1 0.035"/>
      </geometry>
    </collision>
    <inertial>
      <mass value="1.32626"/>
      <origin rpy="0 -0 0" xyz="0.0 0.05 0.05"/>
      <inertia ixx="0.00207537" ixy="0.00011276" ixz="8.927e-05" iyy="0.00240295" iyz="-4.57e-05" izz="0.00141912"/>
    </inertial>
  </link>
  <gazebo reference="gazebo_LARM_JOINT1_Link">
    <material>Gazebo/Black</material>
    <mu1 value="1.0"/>
    <mu2 value="1.0"/>
    <kp value="1e5"/>
    <kd value="1e2"/>
    <maxVel value="100.0"/>
    <minDepth value="0.0"/>
    <dampingFactor>0.01</dampingFactor>
  </gazebo>
  <link name="LARM_JOINT1_Link">
    <visual>
      <origin rpy="0 0 0" xyz="0 0 0"/>
      <geometry>
        <mesh filename="package://nextagea_description/urdf/meshes/LARM_JOINT1_Link_mesh.dae"/>
      </geometry>
    </visual>
    <collision>
      <origin rpy="0 0.3 0" xyz="-0.043 0.12 -0.13"/>
      <geometry>
        <box size="0.08 0.11 0.28"/>
      </geometry>
    </collision>
    <collision>
      <origin rpy="0 0.45 0" xyz="-0.03 0.0518 -0.236"/>
      <geometry>
        <box size="0.122 0.0338 0.062"/>
      </geometry>
    </collision>
    <inertial>
      <mass value="1.14898"/>
      <origin rpy="0 -0 0" xyz="-0.04 0.1 -0.12"/>
      <inertia ixx="0.0154168" ixy="9.95417e-07" ixz="3.38147e-06" iyy="0.0147117" iyz="0.00213719" izz="0.0012658"/>
    </inertial>
  </link>
  <gazebo reference="gazebo_LARM_JOINT2_Link">
    <material>Gazebo/Black</material>
    <mu1 value="1.0"/>
    <mu2 value="1.0"/>
    <kp value="1e5"/>
    <kd value="1e2"/>
    <maxVel value="100.0"/>
    <minDepth value="0.0"/>
    <dampingFactor>0.01</dampingFactor>
  </gazebo>
  <link name="LARM_JOINT2_Link">
    <visual>
      <origin rpy="0 0 0" xyz="0 0 0"/>
      <geometry>
        <mesh filename="package://nextagea_description/urdf/meshes/LARM_JOINT2_Link_mesh.dae"/>
      </geometry>
    </visual>
    <collision>
      <origin rpy="1.57079 0 0" xyz="0 0.025 0"/>
      <geometry>
        <cylinder length="0.11" radius="0.049"/>
      </geometry>
    </collision>
    <collision>
      <origin rpy="0 0 0" xyz="0.0945 0.015 -0.03"/>
      <geometry>
        <box size="0.119 0.125 0.1"/>
      </geometry>
    </collision>
    <collision>
      <origin rpy="0 1.57079 0" xyz="0.17 0 -0.03"/>
      <geometry>
        <cylinder length="0.04" radius="0.047"/>
      </geometry>
    </collision>
    <inertial>
      <mass value="0.577518"/>
      <origin rpy="0 -0 0" xyz="0.1 0.01167107 -0.04"/>
      <inertia ixx="0.00143966" ixy="-3e-07" ixz="1.2e-06" iyy="0.00141763" iyz="-7.596e-05" izz="0.0001972"/>
    </inertial>
  </link>
  <gazebo reference="gazebo_LARM_JOINT3_Link">
    <material>Gazebo/Black</material>
    <mu1 value="1.0"/>
    <mu2 value="1.0"/>
    <kp value="1e5"/>
    <kd value="1e2"/>
    <maxVel value="100.0"/>
    <minDepth value="0.0"/>
    <dampingFactor>0.01</dampingFactor>
  </gazebo>
  <link name="LARM_JOINT3_Link">
    <visual>
      <origin rpy="0 0 0" xyz="0 0 0"/>
      <geometry>
        <mesh filename="package://nextagea_description/urdf/meshes/LARM_JOINT3_Link_mesh.dae"/>
      </geometry>
    </visual>
    <collision>
      <origin rpy="1.57079 0 0" xyz="0.1495 -0.003 0"/>
      <geometry>
        <cylinder length="0.12" radius="0.035"/>
      </geometry>
    </collision>
    <collision>
      <origin rpy="0 1.57079 0" xyz="0.075 0.0 0.018"/>
      <geometry>
        <cylinder length="0.15" radius="0.04"/>
      </geometry>
    </collision>
    <collision>
      <origin rpy="0 0 0" xyz="0.0585 0.01 0.0185"/>
      <geometry>
        <box size="0.093 0.112 0.037"/>
      </geometry>
    </collision>
    <inertial>
      <mass value="0.457418"/>
      <origin rpy="0 -0 0" xyz="0.1 -0.00395812 -0.00273"/>
      <inertia ixx="0.00069205" ixy="3e-08" ixz="5.2e-07" iyy="0.00068903" iyz="-1.915e-05" izz="0.00013509"/>
    </inertial>
  </link>
  <gazebo reference="gazebo_LARM_JOINT4_Link">
    <material>Gazebo/Black</material>
    <mu1 value="1.0"/>
    <mu2 value="1.0"/>
    <kp value="1e5"/>
    <kd value="1e2"/>
    <maxVel value="100.0"/>
    <minDepth value="0.0"/>
    <dampingFactor>0.01</dampingFactor>
  </gazebo>
  <link name="LARM_JOINT4_Link">
    <visual>
      <origin rpy="0 0 0" xyz="0 0 0"/>
      <geometry>
        <mesh filename="package://nextagea_description/urdf/meshes/LARM_JOINT4_Link_mesh.dae"/>
      </geometry>
    </visual>
    <collision>
      <origin rpy="0 0 0" xyz="0 -0.002 -0.06"/>
      <geometry>
        <box size="0.04 0.118 0.06"/>
      </geometry>
    </collision>
    <collision>
      <origin rpy="0 0 0" xyz="0 0 -0.08"/>
      <geometry>
        <cylinder length="0.08" radius="0.037"/>
      </geometry>
    </collision>
    <inertial>
      <mass value="0.418434"/>
      <origin rpy="0 -0 0" xyz="0.00243131 0.00379733 -0.0577036"/>
      <inertia ixx="0.00052016" ixy="1.69e-06" ixz="7.9e-06" iyy="0.00050569" iyz="-5.377e-05" izz="0.00014004"/>
    </inertial>
  </link>
  <gazebo reference="gazebo_LARM_JOINT5_Link">
    <material>Gazebo/Black</material>
    <mu1 value="1.0"/>
    <mu2 value="1.0"/>
    <kp value="1e5"/>
    <kd value="1e2"/>
    <maxVel value="100.0"/>
    <minDepth value="0.0"/>
    <dampingFactor>0.01</dampingFactor>
  </gazebo>
  <link name="LARM_JOINT5_Link">
    <visual>
      <origin rpy="0 0 0" xyz="0 0 0"/>
      <geometry>
        <mesh filename="package://nextagea_description/urdf/meshes/LARM_JOINT5_Link_mesh.dae"/>
      </geometry>
    </visual>
    <collision>
      <origin rpy="0 0 0" xyz="0 0 0.0065"/>
      <geometry>
        <cylinder length="0.013" radius="0.037"/>
      </geometry>
    </collision>
    <inertial>
      <mass value="1.05156"/>
      <origin rpy="0 -0 0" xyz="0.0 0.0 -0.08"/>
      <inertia ixx="0.00194072" ixy="1.1e-07" ixz="-0.00042482" iyy="0.00209392" iyz="1.2e-07" izz="0.00035788"/>
    </inertial>
  </link>
  <gazebo reference="gazebo_RARM_JOINT0_Link">
    <material>Gazebo/Black</material>
    <mu1 value="1.0"/>
    <mu2 value="1.0"/>
    <kp value="1e5"/>
    <kd value="1e2"/>
    <maxVel value="100.0"/>
    <minDepth value="0.0"/>
    <dampingFactor>0.01</dampingFactor>
  </gazebo>
  <link name="RARM_JOINT0_Link">
    <visual>
      <origin rpy="0 0 0" xyz="0 0 0"/>
      <geometry>
        <mesh filename="package://nextagea_description/urdf/meshes/RARM_JOINT0_Link_mesh.dae"/>
      </geometry>
    </visual>
    <collision>
      <origin rpy="0 0 0" xyz="0 -0.00775 0.095"/>
      <geometry>
        <box size="0.1 0.0815 0.19"/>
      </geometry>
    </collision>
    <collision>
      <origin rpy="1.57079 0 0" xyz="0 -0.0875 0.066"/>
      <geometry>
        <cylinder length="0.175" radius="0.042"/>
      </geometry>
    </collision>
    <collision>
      <origin rpy="0.7 0 0" xyz="0 -0.125 0.145"/>
      <geometry>
        <box size="0.048 0.1 0.035"/>
      </geometry>
    </collision>
    <inertial>
      <mass value="1.32626"/>
      <origin rpy="0 -0 0" xyz="0.0 -0.05 0.05"/>
      <inertia ixx="0.00207537" ixy="-0.00011276" ixz="8.927e-05" iyy="0.00240295" iyz="4.57e-05" izz="0.00141912"/>
    </inertial>
  </link>
  <gazebo reference="gazebo_RARM_JOINT1_Link">
    <material>Gazebo/Black</material>
    <mu1 value="1.0"/>
    <mu2 value="1.0"/>
    <kp value="1e5"/>
    <kd value="1e2"/>
    <maxVel value="100.0"/>
    <minDepth value="0.0"/>
    <dampingFactor>0.01</dampingFactor>
  </gazebo>
  <link name="RARM_JOINT1_Link">
    <visual>
      <origin rpy="0 0 0" xyz="0 0 0"/>
      <geometry>
        <mesh filename="package://nextagea_description/urdf/meshes/RARM_JOINT1_Link_mesh.dae"/>
      </geometry>
    </visual>
    <collision>
      <origin rpy="0 0.3 0" xyz="-0.043 -0.12 -0.13"/>
      <geometry>
        <box size="0.08 0.11 0.28"/>
      </geometry>
    </collision>
    <collision>
      <origin rpy="0 0.45 0" xyz="-0.03 -0.0518 -0.236"/>
      <geometry>
        <box size="0.122 0.0338 0.062"/>
      </geometry>
    </collision>
    <inertial>
      <mass value="1.14898"/>
      <origin rpy="0 -0 0" xyz="-0.04 -0.1 -0.12"/>
      <inertia ixx="0.0154168" ixy="-9.95417e-07" ixz="3.38147e-06" iyy="0.0147117" iyz="-0.00213719" izz="0.0012658"/>
    </inertial>
  </link>
  <gazebo reference="gazebo_RARM_JOINT2_Link">
    <material>Gazebo/Black</material>
    <mu1 value="1.0"/>
    <mu2 value="1.0"/>
    <kp value="1e5"/>
    <kd value="1e2"/>
    <maxVel value="100.0"/>
    <minDepth value="0.0"/>
    <dampingFactor>0.01</dampingFactor>
  </gazebo>
  <link name="RARM_JOINT2_Link">
    <visual>
      <origin rpy="0 0 0" xyz="0 0 0"/>
      <geometry>
        <mesh filename="package://nextagea_description/urdf/meshes/RARM_JOINT2_Link_mesh.dae"/>
      </geometry>
    </visual>
    <collision>
      <origin rpy="1.57079 0 0" xyz="0 -0.025 0"/>
      <geometry>
        <cylinder length="0.11" radius="0.049"/>
      </geometry>
    </collision>
    <collision>
      <origin rpy="0 0 0" xyz="0.0945 -0.015 -0.03"/>
      <geometry>
        <box size="0.119 0.125 0.1"/>
      </geometry>
    </collision>
    <collision>
      <origin rpy="0 1.57079 0" xyz="0.17 0 -0.03"/>
      <geometry>
        <cylinder length="0.04" radius="0.047"/>
      </geometry>
    </collision>
    <inertial>
      <mass value="0.577518"/>
      <origin rpy="0 -0 0" xyz="0.1 -0.01167107 -0.04"/>
      <inertia ixx="0.00143966" ixy="3e-07" ixz="1.2e-06" iyy="0.00141763" iyz="7.596e-05" izz="0.0001972"/>
    </inertial>
  </link>
  <gazebo reference="gazebo_RARM_JOINT3_Link">
    <material>Gazebo/Black</material>
    <mu1 value="1.0"/>
    <mu2 value="1.0"/>
    <kp value="1e5"/>
    <kd value="1e2"/>
    <maxVel value="100.0"/>
    <minDepth value="0.0"/>
    <dampingFactor>0.01</dampingFactor>
  </gazebo>
  <link name="RARM_JOINT3_Link">
    <visual>
      <origin rpy="0 0 0" xyz="0 0 0"/>
      <geometry>
        <mesh filename="package://nextagea_description/urdf/meshes/RARM_JOINT3_Link_mesh.dae"/>
      </geometry>
    </visual>
    <collision>
      <origin rpy="1.57079 0 0" xyz="0.1495 -0.003 0"/>
      <geometry>
        <cylinder length="0.12" radius="0.035"/>
      </geometry>
    </collision>
    <collision>
      <origin rpy="0 1.57079 0" xyz="0.075 0.0 0.018"/>
      <geometry>
        <cylinder length="0.15" radius="0.04"/>
      </geometry>
    </collision>
    <collision>
      <origin rpy="0 0 0" xyz="0.0585 -0.01 0.0185"/>
      <geometry>
        <box size="0.093 0.112 0.037"/>
      </geometry>
    </collision>
    <inertial>
      <mass value="0.457418"/>
      <origin rpy="0 -0 0" xyz="0.1 0.00395812 -0.00273"/>
      <inertia ixx="0.00069205" ixy="-3e-08" ixz="5.2e-07" iyy="0.00068903" iyz="1.915e-05" izz="0.00013509"/>
    </inertial>
  </link>
  <gazebo reference="gazebo_RARM_JOINT4_Link">
    <material>Gazebo/Black</material>
    <mu1 value="1.0"/>
    <mu2 value="1.0"/>
    <kp value="1e5"/>
    <kd value="1e2"/>
    <maxVel value="100.0"/>
    <minDepth value="0.0"/>
    <dampingFactor>0.01</dampingFactor>
  </gazebo>
  <link name="RARM_JOINT4_Link">
    <visual>
      <origin rpy="0 0 0" xyz="0 0 0"/>
      <geometry>
        <mesh filename="package://nextagea_description/urdf/meshes/RARM_JOINT4_Link_mesh.dae"/>
      </geometry>
    </visual>
    <collision>
      <origin rpy="0 0 0" xyz="0 -0.002 -0.06"/>
      <geometry>
        <box size="0.04 0.118 0.06"/>
      </geometry>
    </collision>
    <collision>
      <origin rpy="0 0 0" xyz="0 0 -0.08"/>
      <geometry>
        <cylinder length="0.08" radius="0.037"/>
      </geometry>
    </collision>
    <inertial>
      <mass value="0.418434"/>
      <origin rpy="0 -0 0" xyz="0.00243131 -0.00379733 -0.0577036"/>
      <inertia ixx="0.00052016" ixy="-1.69e-06" ixz="7.9e-06" iyy="0.00050569" iyz="5.377e-05" izz="0.00014004"/>
    </inertial>
  </link>
  <gazebo reference="gazebo_RARM_JOINT5_Link">
    <material>Gazebo/Black</material>
    <mu1 value="1.0"/>
    <mu2 value="1.0"/>
    <kp value="1e5"/>
    <kd value="1e2"/>
    <maxVel value="100.0"/>
    <minDepth value="0.0"/>
    <dampingFactor>0.01</dampingFactor>
  </gazebo>
  <link name="RARM_JOINT5_Link">
    <visual>
      <origin rpy="0 0 0" xyz="0 0 0"/>
      <geometry>
        <mesh filename="package://nextagea_description/urdf/meshes/RARM_JOINT5_Link_mesh.dae"/>
      </geometry>
    </visual>
    <collision>
      <origin rpy="0 0 0" xyz="0 0 0.0065"/>
      <geometry>
        <cylinder length="0.013" radius="0.037"/>
      </geometry>
    </collision>
    <inertial>
      <mass value="1.05156"/>
      <origin rpy="0 -0 0" xyz="0.0 0.0 -0.08"/>
      <inertia ixx="0.00194072" ixy="-1.1e-07" ixz="-0.00042482" iyy="0.00209392" iyz="-1.2e-07" izz="0.00035788"/>
    </inertial>
  </link>
  <transmission name="CHEST_JOINT0_Trans">
    <type>transmission_interface/SimpleTransmission</type>
    <joint name="CHEST_JOINT0">
      <hardwareInterface>hardware_interface/PositionJointInterface</hardwareInterface>
    </joint>
    <actuator name="CHEST_JOINT0_Motor">
      <mechanicalReduction>1</mechanicalReduction>
    </actuator>
  </transmission>
  <joint name="CHEST_JOINT0" type="revolute">
    <parent link="WAIST"/>
    <child link="CHEST_JOINT0_Link"/>
    <origin rpy="0 0 0" xyz="0 0 0.267"/>
    <axis xyz="0 0 1"/>
    <limit effort="100" lower="-1.57" upper="1.57" velocity="2.513274"/>
    <dynamics damping="0.2" friction="0"/>
  </joint>
  <transmission name="HEAD_JOINT0_Trans">
    <type>transmission_interface/SimpleTransmission</type>
    <joint name="HEAD_JOINT0">
      <hardwareInterface>hardware_interface/PositionJointInterface</hardwareInterface>
    </joint>
    <actuator name="HEAD_JOINT0_Motor">
      <mechanicalReduction>1</mechanicalReduction>
    </actuator>
  </transmission>
  <joint name="HEAD_JOINT0" type="revolute">
    <parent link="CHEST_JOINT0_Link"/>
    <child link="HEAD_JOINT0_Link"/>
    <origin rpy="0 0 0" xyz="0 0 0.302"/>
    <axis xyz="0 0 1"/>
    <limit effort="100" lower="-1.22173" upper="1.22173" velocity="6.684611"/>
  </joint>
  <transmission name="HEAD_JOINT1_Trans">
    <type>transmission_interface/SimpleTransmission</type>
    <joint name="HEAD_JOINT1">
      <hardwareInterface>hardware_interface/PositionJointInterface</hardwareInterface>
    </joint>
    <actuator name="HEAD_JOINT1_Motor">
      <mechanicalReduction>1</mechanicalReduction>
    </actuator>
  </transmission>
  <joint name="HEAD_JOINT1" type="revolute">
    <parent link="HEAD_JOINT0_Link"/>
    <child link="HEAD_JOINT1_Link"/>
    <origin rpy="0 0 0" xyz="0 0 0.08"/>
    <axis xyz="0 1 0"/>
    <limit effort="100" lower="-0.401425" upper="1.308997" velocity="6.684611"/>
  </joint>
  <transmission name="LARM_JOINT0_Trans">
    <type>transmission_interface/SimpleTransmission</type>
    <joint name="LARM_JOINT0">
      <hardwareInterface>hardware_interface/PositionJointInterface</hardwareInterface>
    </joint>
    <actuator name="LARM_JOINT0_Motor">
      <mechanicalReduction>1</mechanicalReduction>
    </actuator>
  </transmission>
  <joint name="LARM_JOINT0" type="revolute">
    <parent link="CHEST_JOINT0_Link"/>
    <child link="LARM_JOINT0_Link"/>
    <origin rpy="0 0 0" xyz="0.04 0.135 0.1015"/>
    <axis xyz="0 0 1"/>
    <limit effort="150" lower="-1.5707963" upper="1.5707963" velocity="3.892084"/>
    <dynamics damping="0.5" friction="0.5"/>
  </joint>
  <transmission name="LARM_JOINT1_Trans">
    <type>transmission_interface/SimpleTransmission</type>
    <joint name="LARM_JOINT1">
      <hardwareInterface>hardware_interface/PositionJointInterface</hardwareInterface>
    </joint>
    <actuator name="LARM_JOINT1_Motor">
      <mechanicalReduction>1</mechanicalReduction>
    </actuator>
  </transmission>
  <joint name="LARM_JOINT1" type="revolute">
    <parent link="LARM_JOINT0_Link"/>
    <child link="LARM_JOINT1_Link"/>
    <origin rpy="0 0 0" xyz="0 0 0.066"/>
    <axis xyz="0 1 0"/>
    <limit effort="150" lower="-2.44346" upper="1.0471975" velocity="2.426008"/>
    <dynamics damping="0.5" friction="0.5"/>
  </joint>
  <transmission name="LARM_JOINT2_Trans">
    <type>transmission_interface/SimpleTransmission</type>
    <joint name="LARM_JOINT2">
      <hardwareInterface>hardware_interface/PositionJointInterface</hardwareInterface>
    </joint>
    <actuator name="LARM_JOINT2_Motor">
      <mechanicalReduction>1</mechanicalReduction>
    </actuator>
  </transmission>
  <joint name="LARM_JOINT2" type="revolute">
    <parent link="LARM_JOINT1_Link"/>
    <child link="LARM_JOINT2_Link"/>
    <origin rpy="0 0 0" xyz="0 0.095 -0.25"/>
    <axis xyz="0 1 0"/>
    <limit effort="150" lower="-1.22173" upper="1.5707963" velocity="3.630285"/>
    <dynamics damping="0.5" friction="0.5"/>
  </joint>
  <transmission name="LARM_JOINT3_Trans">
    <type>transmission_interface/SimpleTransmission</type>
    <joint name="LARM_JOINT3">
      <hardwareInterface>hardware_interface/PositionJointInterface</hardwareInterface>
    </joint>
    <actuator name="LARM_JOINT3_Motor">
      <mechanicalReduction>1</mechanicalReduction>
    </actuator>
  </transmission>
  <joint name="LARM_JOINT3" type="revolute">
    <parent link="LARM_JOINT2_Link"/>
    <child link="LARM_JOINT3_Link"/>
    <origin rpy="0 0 0" xyz="0.1805 0 -0.03"/>
    <axis xyz="1 0 0"/>
    <limit effort="150" lower="-3.1415926" upper="1.7453292" velocity="6.352998"/>
    <dynamics damping="0.5" friction="0.5"/>
  </joint>
  <transmission name="LARM_JOINT4_Trans">
    <type>transmission_interface/SimpleTransmission</type>
    <joint name="LARM_JOINT4">
      <hardwareInterface>hardware_interface/PositionJointInterface</hardwareInterface>
    </joint>
    <actuator name="LARM_JOINT4_Motor">
      <mechanicalReduction>1</mechanicalReduction>
    </actuator>
  </transmission>
  <joint name="LARM_JOINT4" type="revolute">
    <parent link="LARM_JOINT3_Link"/>
    <child link="LARM_JOINT4_Link"/>
    <origin rpy="0 0 0" xyz="0.1495 0 0"/>
    <axis xyz="0 1 0"/>
    <limit effort="150" lower="-3.4" upper="1.134464" velocity="6.352998"/>
    <dynamics damping="0.5" friction="0.5"/>
  </joint>
  <transmission name="LARM_JOINT5_Trans">
    <type>transmission_interface/SimpleTransmission</type>
    <joint name="LARM_JOINT5">
      <hardwareInterface>hardware_interface/PositionJointInterface</hardwareInterface>
    </joint>
    <actuator name="LARM_JOINT5_Motor">
      <mechanicalReduction>1</mechanicalReduction>
    </actuator>
  </transmission>
  <joint name="LARM_JOINT5" type="revolute">
    <parent link="LARM_JOINT4_Link"/>
    <child link="LARM_JOINT5_Link"/>
    <origin rpy="0 0 0" xyz="0 0 -0.1335"/>
    <axis xyz="0 0 1"/>
    <limit effort="150" lower="-2.7123889" upper="2.7123889" velocity="6.352998"/>
    <dynamics damping="0.5" friction="0.5"/>
  </joint>
  <transmission name="RARM_JOINT0_Trans">
    <type>transmission_interface/SimpleTransmission</type>
    <joint name="RARM_JOINT0">
      <hardwareInterface>hardware_interface/PositionJointInterface</hardwareInterface>
    </joint>
    <actuator name="RARM_JOINT0_Motor">
      <mechanicalReduction>1</mechanicalReduction>
    </actuator>
  </transmission>
  <joint name="RARM_JOINT0" type="revolute">
    <parent link="CHEST_JOINT0_Link"/>
    <child link="RARM_JOINT0_Link"/>
    <origin rpy="0 0 0" xyz="0.04 -0.135 0.1015"/>
    <axis xyz="0 0 1"/>
    <limit effort="150" lower="-1.570796" upper="1.570796" velocity="3.892084"/>
    <dynamics damping="0.5" friction="0.5"/>
  </joint>
  <transmission name="RARM_JOINT1_Trans">
    <type>transmission_interface/SimpleTransmission</type>
    <joint name="RARM_JOINT1">
      <hardwareInterface>hardware_interface/PositionJointInterface</hardwareInterface>
    </joint>
    <actuator name="RARM_JOINT1_Motor">
      <mechanicalReduction>1</mechanicalReduction>
    </actuator>
  </transmission>
  <joint name="RARM_JOINT1" type="revolute">
    <parent link="RARM_JOINT0_Link"/>
    <child link="RARM_JOINT1_Link"/>
    <origin rpy="0 0 0" xyz="0 0 0.066"/>
    <axis xyz="0 1 0"/>
    <limit effort="150" lower="-2.44346" upper="1.047197" velocity="2.426008"/>
    <dynamics damping="0.5" friction="0.5"/>
  </joint>
  <transmission name="RARM_JOINT2_Trans">
    <type>transmission_interface/SimpleTransmission</type>
    <joint name="RARM_JOINT2">
      <hardwareInterface>hardware_interface/PositionJointInterface</hardwareInterface>
    </joint>
    <actuator name="RARM_JOINT2_Motor">
      <mechanicalReduction>1</mechanicalReduction>
    </actuator>
  </transmission>
  <joint name="RARM_JOINT2" type="revolute">
    <parent link="RARM_JOINT1_Link"/>
    <child link="RARM_JOINT2_Link"/>
    <origin rpy="0 0 0" xyz="0 -0.095 -0.25"/>
    <axis xyz="0 1 0"/>
    <limit effort="150" lower="-1.22173" upper="1.570796" velocity="3.630285"/>
    <dynamics damping="0.5" friction="0.5"/>
  </joint>
  <transmission name="RARM_JOINT3_Trans">
    <type>transmission_interface/SimpleTransmission</type>
    <joint name="RARM_JOINT3">
      <hardwareInterface>hardware_interface/PositionJointInterface</hardwareInterface>
    </joint>
    <actuator name="RARM_JOINT3_Motor">
      <mechanicalReduction>1</mechanicalReduction>
    </actuator>
  </transmission>
  <joint name="RARM_JOINT3" type="revolute">
    <parent link="RARM_JOINT2_Link"/>
    <child link="RARM_JOINT3_Link"/>
    <origin rpy="0 0 0" xyz="0.1805 0 -0.03"/>
    <axis xyz="1 0 0"/>
    <limit effort="150" lower="-1.74532" upper="3.141592" velocity="6.352998"/>
    <dynamics damping="0.5" friction="0.5"/>
  </joint>
  <transmission name="RARM_JOINT4_Trans">
    <type>transmission_interface/SimpleTransmission</type>
    <joint name="RARM_JOINT4">
      <hardwareInterface>hardware_interface/PositionJointInterface</hardwareInterface>
    </joint>
    <actuator name="RARM_JOINT4_Motor">
      <mechanicalReduction>1</mechanicalReduction>
    </actuator>
  </transmission>
  <joint name="RARM_JOINT4" type="revolute">
    <parent link="RARM_JOINT3_Link"/>
    <child link="RARM_JOINT4_Link"/>
    <origin rpy="0 0 0" xyz="0.1495 0 0"/>
    <axis xyz="0 1 0"/>
    <limit effort="150" lower="-3.4" upper="1.134464" velocity="6.352998"/>
    <dynamics damping="0.5" friction="0.5"/>
  </joint>
  <transmission name="RARM_JOINT5_Trans">
    <type>transmission_interface/SimpleTransmission</type>
    <joint name="RARM_JOINT5">
      <hardwareInterface>hardware_interface/PositionJointInterface</hardwareInterface>
    </joint>
    <actuator name="RARM_JOINT5_Motor">
      <mechanicalReduction>1</mechanicalReduction>
    </actuator>
  </transmission>
  <joint name="RARM_JOINT5" type="revolute">
    <parent link="RARM_JOINT4_Link"/>
    <child link="RARM_JOINT5_Link"/>
    <origin rpy="0 0 0" xyz="0 0 -0.1335"/>
    <axis xyz="0 0 1"/>
    <limit effort="150" lower="-2.712388" upper="2.712388" velocity="6.352998"/>
    <dynamics damping="0.5" friction="0.5"/>
  </joint>
  <!-- Gazebo-Specific Link Properties -->
  <gazebo reference="CHEST_JOINT0">
    <implicitSpringDamper>1</implicitSpringDamper>
  </gazebo>
  <gazebo reference="HEAD_JOINT0">
    <implicitSpringDamper>1</implicitSpringDamper>
  </gazebo>
  <gazebo reference="HEAD_JOINT1">
    <implicitSpringDamper>1</implicitSpringDamper>
  </gazebo>
  <gazebo reference="LARM_JOINT0">
    <implicitSpringDamper>1</implicitSpringDamper>
  </gazebo>
  <gazebo reference="LARM_JOINT1">
    <implicitSpringDamper>1</implicitSpringDamper>
  </gazebo>
  <gazebo reference="LARM_JOINT2">
    <implicitSpringDamper>1</implicitSpringDamper>
  </gazebo>
  <gazebo reference="LARM_JOINT3">
    <implicitSpringDamper>1</implicitSpringDamper>
  </gazebo>
  <gazebo reference="LARM_JOINT4">
    <implicitSpringDamper>1</implicitSpringDamper>
  </gazebo>
  <gazebo reference="LARM_JOINT5">
    <implicitSpringDamper>1</implicitSpringDamper>
  </gazebo>
  <gazebo reference="RARM_JOINT0">
    <implicitSpringDamper>1</implicitSpringDamper>
  </gazebo>
  <gazebo reference="RARM_JOINT1">
    <implicitSpringDamper>1</implicitSpringDamper>
  </gazebo>
  <gazebo reference="RARM_JOINT2">
    <implicitSpringDamper>1</implicitSpringDamper>
  </gazebo>
  <gazebo reference="RARM_JOINT3">
    <implicitSpringDamper>1</implicitSpringDamper>
  </gazebo>
  <gazebo reference="RARM_JOINT4">
    <implicitSpringDamper>1</implicitSpringDamper>
  </gazebo>
  <gazebo reference="RARM_JOINT5">
    <implicitSpringDamper>1</implicitSpringDamper>
  </gazebo>

<!--  <joint name="donkey_base_link_joint" type="fixed">
    <child link="donkey_base"/>
    <parent link="base_link"/>
    <origin rpy="0 0 0" xyz="0 0 0"/>
  </joint>-->


  <link name="LARM_ft_link_base">
    <visual>
      <origin rpy="0 0 3.665191429188092" xyz="0.01379915772267334 0.051499157722673335 -0.0333"/>
      <geometry>
        <mesh filename="package://nextage_extensions/urdf/meshes/ati-net-gamma.stl" scale="0.001 0.001 0.001"/>
      </geometry>
      <material name="LightGrey">
        <color rgba="0.6 0.6 0.6 1.0"/>
      </material>
    </visual>
    <collision>
      <origin rpy="0 0 0" xyz="0 0 -0.0185"/>
      <geometry>
        <cylinder length="0.037" radius="0.04"/>
      </geometry>
    </collision>
    <inertial>
      <mass value="0.255"/>
      <origin rpy="0 0 0" xyz="0 0 -0.01665"/>
      <inertia ixx="0.00011417115" ixy="0" ixz="0" iyy="0.00011417115" iyz="0" izz="0.00018121447499999996"/>
    </inertial>
  </link>
  <link name="LARM_ft_Sensor_Link">
    <inertial>
      <mass value="0.0001"/>
      <origin rpy="0 0 0" xyz="0 0 0"/>
      <inertia ixx="4.0000000000000006e-13" ixy="0" ixz="0" iyy="4.0000000000000006e-13" iyz="0" izz="4.0000000000000006e-13"/>
    </inertial>
  </link>
  <link name="LARM_ft_link">
    <inertial>
      <mass value="0.0001"/>
      <origin rpy="0 0 0" xyz="0 0 0"/>
      <inertia ixx="4.0000000000000006e-13" ixy="0" ixz="0" iyy="4.0000000000000006e-13" iyz="0" izz="4.0000000000000006e-13"/>
    </inertial>
  </link>
  <joint name="LARM_ft_joint" type="fixed">
    <parent link="LARM_JOINT5_Link"/>
    <child link="LARM_ft_link_base"/>
    <origin rpy="0 0 0" xyz="0 0 0"/>
    <!-- <origin xyz="0 0 0" rpy="0 0 0"/> -->
    <axis xyz="0 0 1"/>
  </joint>
  <joint name="LARM_ft_sensor_joint" type="fixed">
    <parent link="LARM_ft_link_base"/>
    <child link="LARM_ft_Sensor_Link"/>
    <origin rpy="3.141592653589793 0 0" xyz="0 0 -0.0333"/>
    <axis xyz="0 0 1"/>
  </joint>
  <joint name="LARM_ft_sensor_offset_joint" type="fixed">
    <parent link="LARM_ft_Sensor_Link"/>
    <child link="LARM_ft_link"/>
    <origin rpy="0 0 0" xyz="0 0 0"/>
    <axis xyz="0 0 1"/>
  </joint>
  <gazebo reference="LARM_ft_sensor_joint">
    <preserveFixedJoint>true</preserveFixedJoint>
    <disableFixedJointLumping>true</disableFixedJointLumping>
    <sensor name="LARM_ft_sensor" type="force_torque">
      <force_torque>
        <frame>parent</frame>
        <measure_direction>child_to_parent</measure_direction>
      </force_torque>
    </sensor>
  </gazebo>
  <gazebo>
    <plugin filename="libgazebo_ros_ft_sensor.so" name="LARM_ft_sensor">
      <updateRate>500.0</updateRate>
      <topicName>ft_left/raw/data</topicName>
      <jointName>LARM_ft_sensor_joint</jointName>
    </plugin>
  </gazebo>
  <link name="RARM_ft_link_base">
    <visual>
      <origin rpy="0 0 3.665191429188092" xyz="0.01379915772267334 0.051499157722673335 -0.0333"/>
      <geometry>
        <mesh filename="package://nextage_extensions/urdf/meshes/ati-net-gamma.stl" scale="0.001 0.001 0.001"/>
      </geometry>
      <material name="LightGrey">
        <color rgba="0.6 0.6 0.6 1.0"/>
      </material>
    </visual>
    <collision>
      <origin rpy="0 0 0" xyz="0 0 -0.0185"/>
      <geometry>
        <cylinder length="0.037" radius="0.04"/>
      </geometry>
    </collision>
    <inertial>
      <mass value="0.255"/>
      <origin rpy="0 0 0" xyz="0 0 -0.01665"/>
      <inertia ixx="0.00011417115" ixy="0" ixz="0" iyy="0.00011417115" iyz="0" izz="0.00018121447499999996"/>
    </inertial>
  </link>
  <link name="RARM_ft_Sensor_Link">
    <inertial>
      <mass value="0.0001"/>
      <origin rpy="0 0 0" xyz="0 0 0"/>
      <inertia ixx="4.0000000000000006e-13" ixy="0" ixz="0" iyy="4.0000000000000006e-13" iyz="0" izz="4.0000000000000006e-13"/>
    </inertial>
  </link>
  <link name="RARM_ft_link">
    <inertial>
      <mass value="0.0001"/>
      <origin rpy="0 0 0" xyz="0 0 0"/>
      <inertia ixx="4.0000000000000006e-13" ixy="0" ixz="0" iyy="4.0000000000000006e-13" iyz="0" izz="4.0000000000000006e-13"/>
    </inertial>
  </link>
  <joint name="RARM_ft_joint" type="fixed">
    <parent link="RARM_JOINT5_Link"/>
    <child link="RARM_ft_link_base"/>
    <origin rpy="0 0 0" xyz="0 0 0"/>
    <!-- <origin xyz="0 0 0" rpy="0 0 0"/> -->
    <axis xyz="0 0 1"/>
  </joint>
  <joint name="RARM_ft_sensor_joint" type="fixed">
    <parent link="RARM_ft_link_base"/>
    <child link="RARM_ft_Sensor_Link"/>
    <origin rpy="3.141592653589793 0 0" xyz="0 0 -0.0333"/>
    <axis xyz="0 0 1"/>
  </joint>
  <joint name="RARM_ft_sensor_offset_joint" type="fixed">
    <parent link="RARM_ft_Sensor_Link"/>
    <child link="RARM_ft_link"/>
    <origin rpy="0 0 0" xyz="0 0 0"/>
    <axis xyz="0 0 1"/>
  </joint>
  <gazebo reference="RARM_ft_sensor_joint">
    <preserveFixedJoint>true</preserveFixedJoint>
    <disableFixedJointLumping>true</disableFixedJointLumping>
    <sensor name="RARM_ft_sensor" type="force_torque">
      <force_torque>
        <frame>parent</frame>
        <measure_direction>child_to_parent</measure_direction>
      </force_torque>
    </sensor>
  </gazebo>
  <gazebo>
    <plugin filename="libgazebo_ros_ft_sensor.so" name="RARM_ft_sensor">
      <updateRate>500.0</updateRate>
      <topicName>ft_right/raw/data</topicName>
      <jointName>RARM_ft_sensor_joint</jointName>
    </plugin>
  </gazebo>
  <link name="LARM_changer_link_base">
    <visual>
      <origin rpy="0 0 -1.5707963267948966" xyz="0.002 0 0.011"/>
      <geometry>
        <mesh filename="package://nextage_extensions/urdf/meshes/tool_changer.stl" scale="0.001 0.001 0.001"/>
      </geometry>
      <material name="LightGrey">
        <color rgba="0.6 0.6 0.6 1.0"/>
      </material>
    </visual>
    <collision>
      <origin rpy="0 0 0" xyz="0 0 0.0195"/>
      <geometry>
        <cylinder length="0.039" radius="0.03505"/>
      </geometry>
    </collision>
    <inertial>
      <mass value="0.200"/>
      <origin rpy="0 0 0" xyz="0 0 0.0195"/>
      <inertia ixx="8.677512500000001e-05" ixy="0" ixz="0" iyy="8.677512500000001e-05" iyz="0" izz="0.00012285024999999998"/>
    </inertial>
  </link>
  <link name="LARM_changer_link">
    <inertial>
      <mass value="0.0001"/>
      <origin rpy="0 0 0" xyz="0 0 0"/>
      <inertia ixx="4.0000000000000006e-13" ixy="0" ixz="0" iyy="4.0000000000000006e-13" iyz="0" izz="4.0000000000000006e-13"/>
    </inertial>
  </link>
  <joint name="LARM_changer_robot_side_joint" type="fixed">
    <parent link="LARM_ft_link"/>
    <child link="LARM_changer_link_base"/>
    <origin rpy="0 0 0" xyz="0 0 0"/>
    <!-- <origin xyz="0 0 0" rpy="0 0 0"/> -->
    <axis xyz="0 0 1"/>
  </joint>
  <joint name="LARM_changer_tool_side_joint" type="fixed">
    <parent link="LARM_changer_link_base"/>
    <child link="LARM_changer_link"/>
    <origin rpy="0 0 0" xyz="0 0 0.039"/>
    <axis xyz="0 0 1"/>
  </joint>
  <link name="RARM_changer_link_base">
    <visual>
      <origin rpy="0 0 -1.5707963267948966" xyz="0.002 0 0.011"/>
      <geometry>
        <mesh filename="package://nextage_extensions/urdf/meshes/tool_changer.stl" scale="0.001 0.001 0.001"/>
      </geometry>
      <material name="LightGrey">
        <color rgba="0.6 0.6 0.6 1.0"/>
      </material>
    </visual>
    <collision>
      <origin rpy="0 0 0" xyz="0 0 0.0195"/>
      <geometry>
        <cylinder length="0.039" radius="0.03505"/>
      </geometry>
    </collision>
    <inertial>
      <mass value="0.200"/>
      <origin rpy="0 0 0" xyz="0 0 0.0195"/>
      <inertia ixx="8.677512500000001e-05" ixy="0" ixz="0" iyy="8.677512500000001e-05" iyz="0" izz="0.00012285024999999998"/>
    </inertial>
  </link>
  <link name="RARM_changer_link">
    <inertial>
      <mass value="0.0001"/>
      <origin rpy="0 0 0" xyz="0 0 0"/>
      <inertia ixx="4.0000000000000006e-13" ixy="0" ixz="0" iyy="4.0000000000000006e-13" iyz="0" izz="4.0000000000000006e-13"/>
    </inertial>
  </link>
  <joint name="RARM_changer_robot_side_joint" type="fixed">
    <parent link="RARM_ft_link"/>
    <child link="RARM_changer_link_base"/>
    <origin rpy="0 0 0" xyz="0 0 0"/>
    <!-- <origin xyz="0 0 0" rpy="0 0 0"/> -->
    <axis xyz="0 0 1"/>
  </joint>
  <joint name="RARM_changer_tool_side_joint" type="fixed">
    <parent link="RARM_changer_link_base"/>
    <child link="RARM_changer_link"/>
    <origin rpy="0 0 0" xyz="0 0 0.039"/>
    <axis xyz="0 0 1"/>
  </joint>
  <link name="LARM_END_EFFECTOR">
    <visual>
      <origin rpy="0 0 0" xyz="0 0 0"/>
      <geometry>
        <mesh filename="package://chonk_pushing/urdf/meshes/end_effector.stl" scale="0.001 0.001 0.001"/>
      </geometry>
      <material name="Grey"/>
    </visual>
    <inertial>
      <mass value="0.01"/>
      <origin rpy="0 0 0" xyz="0 0 0.03"/>
      <inertia ixx="6.666666666666668e-07" ixy="0.0" ixz="0.0" iyy="6.666666666666668e-07" iyz="0.0" izz="6.666666666666668e-07"/>
    </inertial>
  </link>
  <!-- end-effector root -->
  <joint name="LARM_ARM_eeff" type="fixed">
    <parent link="LARM_changer_link"/>
    <child link="LARM_END_EFFECTOR"/>
    <origin rpy="0 0 0" xyz="0 0 0"/>
  </joint>
  <!-- sliding frame at tip of spherical extension -->
  <joint name="LARM_ARM_eeff_finger" type="fixed">
    <parent link="LARM_END_EFFECTOR"/>
    <child link="LARM_END_EFFECTOR_finger"/>
    <origin rpy="0 0 0" xyz="-0.02 0 0.075"/>
  </joint>
  <link name="LARM_END_EFFECTOR_finger">
    <collision>
      <origin rpy="0 0 0" xyz="0 0 0"/>
      <geometry>
        <sphere radius="0.0125"/>
      </geometry>
    </collision>
    <inertial>
      <mass value="0.001"/>
      <origin rpy="0 0 0" xyz="0 0 0"/>
      <inertia ixx="6.250000000000001e-08" ixy="0" ixz="0" iyy="6.250000000000001e-08" iyz="0" izz="6.250000000000001e-08"/>
    </inertial>
  </link>
  <!-- grasp frame at centre of flat extension -->
  <joint name="LARM_ARM_eeff_grasp" type="fixed">
    <parent link="LARM_END_EFFECTOR"/>
    <child link="LARM_END_EFFECTOR_grasp"/>
    <origin rpy="0 -1.5707963267948966 0" xyz="-0.08 0 0.04"/>
  </joint>
  <link name="LARM_END_EFFECTOR_grasp">
    <inertial>
      <mass value="0.05"/>
      <origin rpy="0 0 0" xyz="0 0 0"/>
      <inertia ixx="8.333333333333334e-09" ixy="0.0" ixz="0.0" iyy="8.333333333333334e-09" iyz="0.0" izz="8.333333333333334e-09"/>
    </inertial>
  </link>
  <!-- offset from grasp frame to the tip of the flat contact (diameter: 9cm) -->
  <joint name="LARM_ARM_eeff_grasp_end" type="fixed">
    <parent link="LARM_END_EFFECTOR_grasp"/>
    <child link="LARM_END_EFFECTOR_grasp_end"/>
    <origin xyz="0.045 0 0"/>
  </joint>
  <link name="LARM_END_EFFECTOR_grasp_end">
    <collision>
      <origin rpy="0 0 0" xyz="-0.045 0 -0.0025"/>
      <geometry>
        <cylinder length="0.005" radius="0.045"/>
      </geometry>
    </collision>
    <inertial>
      <mass value="0.05"/>
      <origin rpy="0 0 0" xyz="0 0 0"/>
      <inertia ixx="2.541666666666667e-05" ixy="0" ixz="0" iyy="2.541666666666667e-05" iyz="0" izz="5.0625e-05"/>
    </inertial>
  </link>
  <gazebo reference="LARM_END_EFFECTOR_grasp_end">
    <collision>
      <surface>
        <contact>
          <ode>
            <soft_cfm>0</soft_cfm>
            <soft_erp>0.2</soft_erp>
            <kp>1e+6</kp>
            <kd>1e3</kd>
            <max_vel>0.1</max_vel>
            <min_depth>0.01</min_depth>
          </ode>
        </contact>
      </surface>
    </collision>
  </gazebo>
  <link name="RARM_END_EFFECTOR">
    <visual>
      <origin rpy="0 0 0" xyz="0 0 0"/>
      <geometry>
        <mesh filename="package://chonk_pushing/urdf/meshes/end_effector.stl" scale="0.001 0.001 0.001"/>
      </geometry>
      <material name="Grey"/>
    </visual>
    <inertial>
      <mass value="0.01"/>
      <origin rpy="0 0 0" xyz="0 0 0.03"/>
      <inertia ixx="6.666666666666668e-07" ixy="0.0" ixz="0.0" iyy="6.666666666666668e-07" iyz="0.0" izz="6.666666666666668e-07"/>
    </inertial>
  </link>
  <!-- end-effector root -->
  <joint name="RARM_ARM_eeff" type="fixed">
    <parent link="RARM_changer_link"/>
    <child link="RARM_END_EFFECTOR"/>
    <origin rpy="0 0 0" xyz="0 0 0"/>
  </joint>
  <!-- sliding frame at tip of spherical extension -->
  <joint name="RARM_ARM_eeff_finger" type="fixed">
    <parent link="RARM_END_EFFECTOR"/>
    <child link="RARM_END_EFFECTOR_finger"/>
    <origin rpy="0 0 0" xyz="-0.02 0 0.075"/>
  </joint>
  <link name="RARM_END_EFFECTOR_finger">
    <collision>
      <origin rpy="0 0 0" xyz="0 0 0"/>
      <geometry>
        <sphere radius="0.0125"/>
      </geometry>
    </collision>
    <inertial>
      <mass value="0.001"/>
      <origin rpy="0 0 0" xyz="0 0 0"/>
      <inertia ixx="6.250000000000001e-08" ixy="0" ixz="0" iyy="6.250000000000001e-08" iyz="0" izz="6.250000000000001e-08"/>
    </inertial>
  </link>
  <!-- grasp frame at centre of flat extension -->
  <joint name="RARM_ARM_eeff_grasp" type="fixed">
    <parent link="RARM_END_EFFECTOR"/>
    <child link="RARM_END_EFFECTOR_grasp"/>
    <origin rpy="0 -1.5707963267948966 0" xyz="-0.08 0 0.04"/>
  </joint>
  <link name="RARM_END_EFFECTOR_grasp">
    <inertial>
      <mass value="0.05"/>
      <origin rpy="0 0 0" xyz="0 0 0"/>
      <inertia ixx="8.333333333333334e-09" ixy="0.0" ixz="0.0" iyy="8.333333333333334e-09" iyz="0.0" izz="8.333333333333334e-09"/>
    </inertial>
  </link>
  <!-- offset from grasp frame to the tip of the flat contact (diameter: 9cm) -->
  <joint name="RARM_ARM_eeff_grasp_end" type="fixed">
    <parent link="RARM_END_EFFECTOR_grasp"/>
    <child link="RARM_END_EFFECTOR_grasp_end"/>
    <origin xyz="0.045 0 0"/>
  </joint>
  <link name="RARM_END_EFFECTOR_grasp_end">
    <collision>
      <origin rpy="0 0 0" xyz="-0.045 0 -0.0025"/>
      <geometry>
        <cylinder length="0.005" radius="0.045"/>
      </geometry>
    </collision>
    <inertial>
      <mass value="0.05"/>
      <origin rpy="0 0 0" xyz="0 0 0"/>
      <inertia ixx="2.541666666666667e-05" ixy="0" ixz="0" iyy="2.541666666666667e-05" iyz="0" izz="5.0625e-05"/>
    </inertial>
  </link>
  <gazebo reference="RARM_END_EFFECTOR_grasp_end">
    <collision>
      <surface>
        <contact>
          <ode>
            <soft_cfm>0</soft_cfm>
            <soft_erp>0.2</soft_erp>
            <kp>1e+6</kp>
            <kd>1e3</kd>
            <max_vel>0.1</max_vel>
            <min_depth>0.01</min_depth>
          </ode>
        </contact>
      </surface>
    </collision>
  </gazebo>
  <!-- chonk head frame -->
  <link name="CAMERA_HEAD_Link"/>
  <joint name="CAMERA_HEAD_Joint" type="fixed">
    <parent link="CAMERA_HEAD_R_Link"/>
    <child link="CAMERA_HEAD_Link"/>
    <origin rpy="0 0 0" xyz="0 0.0725 0"/>
  </joint>
  <link name="CAMERA_HEAD_HEADING_Link"/>
  <joint name="CAMERA_HEAD_HEADING_Joint" type="fixed">
    <parent link="HEAD_JOINT1_Link"/>
    <child link="CAMERA_HEAD_HEADING_Link"/>
    <origin rpy="0 0 0" xyz="1.2 0 0"/>
  </joint>
  <!-- teleop frame for reference-->
  <link name="teleop_ref"/>
  <joint name="teleop_ref_joint" type="fixed">
    <parent link="base_link"/>
    <child link="teleop_ref"/>
    <origin rpy="3.14159 0 0" xyz="0.3 0 0"/>
  </joint>
  <!-- gaze reference -->
  <link name="gaze_ref"/>
  <joint name="gaze_ref_joint" type="fixed">
    <parent link="RARM_END_EFFECTOR_finger"/>
    <child link="gaze_ref"/>
    <origin rpy="0 0 0" xyz="0.25 0 0"/>
  </joint>
  <!-- Grippers -->
  <!--    <xacro:robotiq_140_gripper prefix="LARM_" parent="LARM_changer_link">
        <origin xyz="0 0 0" rpy="0 0 0"/>
    </xacro:robotiq_140_gripper>-->
  <!--    <xacro:robotiq_140_gripper prefix="RARM_" parent="RARM_changer_link">
        <origin xyz="0 0 0" rpy="0 0 0"/>
    </xacro:robotiq_140_gripper>-->
  <gazebo>
    <plugin filename="libgazebo_ros_control.so" name="gazebo_ros_control">
      <robotNamespace>/chonk</robotNamespace>
    </plugin>
  </gazebo>
  <!-- Attach the RealSense D435 -->
  <joint name="intel_realsense_d435_mount_joint" type="fixed">
    <origin rpy="0 0.24902114520034205 0" xyz="0 0 0.1448322"/>
    <parent link="HEAD_JOINT1_Link"/>
    <child link="intel_realsense_d435_Mount_Link"/>
  </joint>
  <link name="intel_realsense_d435_Mount_Link">
    <inertial>
      <mass value="0.01"/>
      <origin rpy="0 0 0" xyz="0 0 0"/>
      <inertia ixx="1.6000000000000001e-06" ixy="0" ixz="0" iyy="1.6000000000000001e-06" iyz="0" izz="1.6000000000000001e-06"/>
    </inertial>
  </link>
  <!-- camera body, with origin at bottom screw mount -->
  <joint name="intel_realsense_joint" type="fixed">
    <origin rpy="0 0 0" xyz="0 0 0"/>
    <parent link="intel_realsense_d435_Mount_Link"/>
    <child link="intel_realsense_bottom_screw_frame"/>
  </joint>
  <link name="intel_realsense_bottom_screw_frame"/>
  <joint name="intel_realsense_link_joint" type="fixed">
    <origin rpy="0 0 0" xyz="0.010600000000000002 0.0175 0.0125"/>
    <parent link="intel_realsense_bottom_screw_frame"/>
    <child link="intel_realsense_link"/>
  </joint>
  <link name="intel_realsense_link">
    <visual>
      <!-- the mesh origin is at front plate in between the two infrared camera axes -->
      <origin rpy="1.5707963267948966 0 1.5707963267948966" xyz="0.0043 -0.0175 0"/>
      <geometry>
        <mesh filename="package://realsense2_description/meshes/d435.dae"/>
      </geometry>
    </visual>
    <collision>
      <origin rpy="0 0 0" xyz="0 -0.0175 0"/>
      <geometry>
        <box size="0.02505 0.09 0.025"/>
      </geometry>
    </collision>
    <inertial>
      <!-- The following are not reliable values, and should not be used for modeling -->
      <mass value="0.072"/>
      <origin xyz="0 0 0"/>
      <inertia ixx="0.003881243" ixy="0.0" ixz="0.0" iyy="0.000498940" iyz="0.0" izz="0.003879257"/>
    </inertial>
  </link>
  <!-- camera depth joints and links -->
  <joint name="intel_realsense_depth_joint" type="fixed">
    <origin rpy="0 0 0" xyz="0 0 0"/>
    <parent link="intel_realsense_link"/>
    <child link="intel_realsense_depth_frame"/>
  </joint>
  <link name="intel_realsense_depth_frame"/>
  <joint name="intel_realsense_depth_optical_joint" type="fixed">
    <origin rpy="-1.5707963267948966 0 -1.5707963267948966" xyz="0 0 0"/>
    <parent link="intel_realsense_depth_frame"/>
    <child link="intel_realsense_depth_optical_frame"/>
  </joint>
  <link name="intel_realsense_depth_optical_frame"/>
  <!-- camera left IR joints and links -->
  <joint name="intel_realsense_infra1_joint" type="fixed">
    <origin rpy="0 0 0" xyz="0 0.0 0"/>
    <parent link="intel_realsense_link"/>
    <child link="intel_realsense_infra1_frame"/>
  </joint>
  <link name="intel_realsense_infra1_frame"/>
  <joint name="intel_realsense_infra1_optical_joint" type="fixed">
    <origin rpy="-1.5707963267948966 0 -1.5707963267948966" xyz="0 0 0"/>
    <parent link="intel_realsense_infra1_frame"/>
    <child link="intel_realsense_infra1_optical_frame"/>
  </joint>
  <link name="intel_realsense_infra1_optical_frame"/>
  <!-- camera right IR joints and links -->
  <joint name="intel_realsense_infra2_joint" type="fixed">
    <origin rpy="0 0 0" xyz="0 -0.05 0"/>
    <parent link="intel_realsense_link"/>
    <child link="intel_realsense_infra2_frame"/>
  </joint>
  <link name="intel_realsense_infra2_frame"/>
  <joint name="intel_realsense_infra2_optical_joint" type="fixed">
    <origin rpy="-1.5707963267948966 0 -1.5707963267948966" xyz="0 0 0"/>
    <parent link="intel_realsense_infra2_frame"/>
    <child link="intel_realsense_infra2_optical_frame"/>
  </joint>
  <link name="intel_realsense_infra2_optical_frame"/>
  <!-- camera color joints and links -->
  <joint name="intel_realsense_color_joint" type="fixed">
    <origin rpy="0 0 0" xyz="0 0.015 0"/>
    <parent link="intel_realsense_link"/>
    <child link="intel_realsense_color_frame"/>
  </joint>
  <link name="intel_realsense_color_frame"/>
  <joint name="intel_realsense_color_optical_joint" type="fixed">
    <origin rpy="-1.5707963267948966 0 -1.5707963267948966" xyz="0 0 0"/>
    <parent link="intel_realsense_color_frame"/>
    <child link="intel_realsense_color_optical_frame"/>
  </joint>
  <link name="intel_realsense_color_optical_frame"/>
  <gazebo reference="intel_realsense_color_frame">
    <sensor name="color" type="camera">
      <pose frame="">0 0 0 0 0 0</pose>
      <camera name="__default__">
        <horizontal_fov>1.5009831567151233</horizontal_fov>
        <image>
          <width>640</width>
          <height>480</height>
          <format>RGB_INT8</format>
        </image>
        <clip>
          <near>0.1</near>
          <far>100</far>
        </clip>
        <noise>
          <type>gaussian</type>
          <mean>0.0</mean>
          <stddev>0.007</stddev>
        </noise>
      </camera>
      <always_on>1</always_on>
      <update_rate>30</update_rate>
      <visualize>1</visualize>
    </sensor>
  </gazebo>
  <gazebo reference="intel_realsense_infra1_frame">
    <sensor name="ired1" type="camera">
      <pose frame="">0 0 0 0 0 0</pose>
      <camera name="__default__">
        <horizontal_fov>1.5009831567151233</horizontal_fov>
        <image>
          <width>640</width>
          <height>480</height>
          <format>L_INT8</format>
        </image>
        <clip>
          <near>0.1</near>
          <far>100</far>
        </clip>
        <noise>
          <type>gaussian</type>
          <mean>0.0</mean>
          <stddev>0.007</stddev>
        </noise>
      </camera>
      <always_on>1</always_on>
      <update_rate>30</update_rate>
      <visualize>0</visualize>
    </sensor>
  </gazebo>
  <gazebo reference="intel_realsense_infra2_frame">
    <sensor name="ired2" type="camera">
      <pose frame="">0 0 0 0 0 0</pose>
      <camera name="__default__">
        <horizontal_fov>1.5009831567151233</horizontal_fov>
        <image>
          <width>640</width>
          <height>480</height>
          <format>L_INT8</format>
        </image>
        <clip>
          <near>0.1</near>
          <far>100</far>
        </clip>
        <noise>
          <type>gaussian</type>
          <mean>0.0</mean>
          <stddev>0.007</stddev>
        </noise>
      </camera>
      <always_on>1</always_on>
      <update_rate>30</update_rate>
      <visualize>0</visualize>
    </sensor>
  </gazebo>
  <gazebo reference="intel_realsense_depth_frame">
    <sensor name="depth" type="depth">
      <pose frame="">0 0 0 0 0 0</pose>
      <camera name="__default__">
        <horizontal_fov>1.5009831567151233</horizontal_fov>
        <image>
          <width>640</width>
          <height>480</height>
        </image>
        <clip>
          <near>0.1</near>
          <far>100</far>
        </clip>
        <noise>
          <type>gaussian</type>
          <mean>0.0</mean>
          <stddev>0.007</stddev>
        </noise>
      </camera>
      <always_on>1</always_on>
      <update_rate>30</update_rate>
      <visualize>0</visualize>
    </sensor>
  </gazebo>
  <gazebo>
    <plugin filename="librealsense_gazebo_plugin.so" name="intel_realsense">
      <depthUpdateRate>30</depthUpdateRate>
      <colorUpdateRate>30</colorUpdateRate>
      <infraredUpdateRate>30</infraredUpdateRate>
      <depthTopicName>depth/image_rect_raw</depthTopicName>
      <depthCameraInfoTopicName>depth/camera_info</depthCameraInfoTopicName>
      <colorTopicName>color/image_raw</colorTopicName>
      <colorCameraInfoTopicName>color/camera_info</colorCameraInfoTopicName>
      <infrared1TopicName>infrared/image_raw</infrared1TopicName>
      <infrared1CameraInfoTopicName>infrared/camera_info</infrared1CameraInfoTopicName>
      <infrared2TopicName>infrared2/image_raw</infrared2TopicName>
      <infrared2CameraInfoTopicName>infrared2/camera_info</infrared2CameraInfoTopicName>
      <colorOpticalframeName>intel_realsense_color_optical_frame</colorOpticalframeName>
      <depthOpticalframeName>intel_realsense_depth_optical_frame</depthOpticalframeName>
      <infrared1OpticalframeName>intel_realsense_left_ir_optical_frame</infrared1OpticalframeName>
      <infrared2OpticalframeName>intel_realsense_right_ir_optical_frame</infrared2OpticalframeName>
      <rangeMinDepth>0.1</rangeMinDepth>
      <rangeMaxDepth>10</rangeMaxDepth>
      <pointCloud>1</pointCloud>
      <pointCloudTopicName>depth/color/points</pointCloudTopicName>
      <pointCloudCutoff>0.15</pointCloudCutoff>
      <pointCloudCutoffMax>10</pointCloudCutoffMax>
    </plugin>
  </gazebo>
</robot>
